Workbook

Sheet Сводка
A1: Карта связей прототипа «Ноготочки»
A2: Дата составления: 18.09.2026. Источник — план экранов и промпты для Claude Design, согласованные в работе над проектом.
A4: Показатель | B4: Значение
A5: Всего экранов в прототипе | B5: =COUNTA(Экраны!$A$2:$A$32)
A6: Экранов клиента и публичной части | B6: =COUNTIF(Экраны!$C$2:$C$32,"Гость")+COUNTIF(Экраны!$C$2:$C$32,"Гость / Клиент")+COUNTIF(Экраны!$C$2:$C$32,"Клиент")
A7: Экранов мастера | B7: =COUNTIF(Экраны!$C$2:$C$32,"Мастер")
A8: Экранов администратора | B8: =COUNTIF(Экраны!$C$2:$C$32,"Администратор")
A9: Всего переходов | B9: =COUNTA(Переходы!$A$2:$A$109)
A10: Основных переходов | B10: =COUNTIF(Переходы!$F$2:$F$109,"Основной")
A11: Переходов назад | B11: =COUNTIF(Переходы!$F$2:$F$109,"Возврат")
A12: Переходов по меню | B12: =COUNTIF(Переходы!$F$2:$F$109,"Меню")
A13: Переходов из состояний ошибок | B13: =COUNTIF(Переходы!$F$2:$F$109,"Ошибка")
A14: Экранов без входа (недостижимых) | B14: =COUNTIF(Экраны!$H$2:$H$32,"Нет входа — недостижимый экран")
A15: Экранов без выхода (тупиков) | B15: =COUNTIF(Экраны!$H$2:$H$32,"Нет выхода — тупик")
A18: Как читать файл:
A19: • Лист «Экраны» — 31 экран прототипа. Столбцы «Входов» и «Выходов» считаются формулами по листу «Переходы», столбец «Проверка» сам помечает недостижимые экраны и тупики.
A20: • Лист «Переходы» — все связи между экранами: откуда, куда, по какому действию и какого типа.
A21: • Лист «Этапы связывания» — 8 этапов работы, столбец «Статус» заполняете вы по мере проверки.
A22: • Добавили экран или связь — просто допишите строку: показатели на этом листе пересчитаются сами.
A23: • Страница «Nogotochki Design System» в карту не входит: это гайд, а не экран.

Sheet Экраны
A1: ID | B1: Раздел | C1: Роль | D1: Название страницы в Claude Design | E1: Назначение экрана | F1: Входов | G1: Выходов | H1: Проверка
A2: L1 | B2: Публичная часть | C2: Гость | D2: Главная — лендинг | E2: Информация о студии, услугах и мастерах; вход в запись и в аккаунт | F2: =COUNTIF(Переходы!$C:$C,$A2) | G2: =COUNTIF(Переходы!$A:$A,$A2) | H2: =IF(F2=0,"Нет входа — недостижимый экран",IF(G2=0,"Нет выхода — тупик","OK"))
A3: C1 | B3: Авторизация | C3: Гость | D3: Вход | E3: Вход клиента по e-mail и паролю | F3: =COUNTIF(Переходы!$C:$C,$A3) | G3: =COUNTIF(Переходы!$A:$A,$A3) | H3: =IF(F3=0,"Нет входа — недостижимый экран",IF(G3=0,"Нет выхода — тупик","OK"))
A4: C2 | B4: Авторизация | C4: Гость | D4: Регистрация | E4: Создание аккаунта клиента | F4: =COUNTIF(Переходы!$C:$C,$A4) | G4: =COUNTIF(Переходы!$A:$A,$A4) | H4: =IF(F4=0,"Нет входа — недостижимый экран",IF(G4=0,"Нет выхода — тупик","OK"))
A5: C3 | B5: Авторизация | C5: Гость | D5: Восстановление пароля — запрос | E5: Отправка ссылки для смены пароля | F5: =COUNTIF(Переходы!$C:$C,$A5) | G5: =COUNTIF(Переходы!$A:$A,$A5) | H5: =IF(F5=0,"Нет входа — недостижимый экран",IF(G5=0,"Нет выхода — тупик","OK"))
A6: C4 | B6: Авторизация | C6: Гость | D6: Восстановление пароля — новый пароль | E6: Ввод нового пароля по ссылке из письма | F6: =COUNTIF(Переходы!$C:$C,$A6) | G6: =COUNTIF(Переходы!$A:$A,$A6) | H6: =IF(F6=0,"Нет входа — недостижимый экран",IF(G6=0,"Нет выхода — тупик","OK"))
A7: B1 | B7: Путь записи | C7: Гость / Клиент | D7: Запись. Шаг 1 — Услуги | E7: Выбор нескольких услуг, расчёт длительности и суммы | F7: =COUNTIF(Переходы!$C:$C,$A7) | G7: =COUNTIF(Переходы!$A:$A,$A7) | H7: =IF(F7=0,"Нет входа — недостижимый экран",IF(G7=0,"Нет выхода — тупик","OK"))
A8: B2 | B8: Путь записи | C8: Гость / Клиент | D8: Запись. Шаг 2 — Мастер | E8: Выбор мастера или варианта «Любой мастер» | F8: =COUNTIF(Переходы!$C:$C,$A8) | G8: =COUNTIF(Переходы!$A:$A,$A8) | H8: =IF(F8=0,"Нет входа — недостижимый экран",IF(G8=0,"Нет выхода — тупик","OK"))
A9: B3 | B9: Путь записи | C9: Гость / Клиент | D9: Запись. Шаг 3 — Дата и время | E9: Календарь на 3 месяца и свободные слоты, старт резерва | F9: =COUNTIF(Переходы!$C:$C,$A9) | G9: =COUNTIF(Переходы!$A:$A,$A9) | H9: =IF(F9=0,"Нет входа — недостижимый экран",IF(G9=0,"Нет выхода — тупик","OK"))
A10: B4 | B10: Путь записи | C10: Гость | D10: Запись. Шаг 4 — Вход в процессе записи | E10: Вход или регистрация с сохранением резерва | F10: =COUNTIF(Переходы!$C:$C,$A10) | G10: =COUNTIF(Переходы!$A:$A,$A10) | H10: =IF(F10=0,"Нет входа — недостижимый экран",IF(G10=0,"Нет выхода — тупик","OK"))
A11: B5 | B11: Путь записи | C11: Клиент | D11: Запись. Шаг 5 — Подтверждение | E11: Сводка записи, таймер резерва, подтверждение | F11: =COUNTIF(Переходы!$C:$C,$A11) | G11: =COUNTIF(Переходы!$A:$A,$A11) | H11: =IF(F11=0,"Нет входа — недостижимый экран",IF(G11=0,"Нет выхода — тупик","OK"))
A12: B6 | B12: Путь записи | C12: Клиент | D12: Запись подтверждена | E12: Результат записи или переноса | F12: =COUNTIF(Переходы!$C:$C,$A12) | G12: =COUNTIF(Переходы!$A:$A,$A12) | H12: =IF(F12=0,"Нет входа — недостижимый экран",IF(G12=0,"Нет выхода — тупик","OK"))
A13: K1 | B13: Кабинет клиента | C13: Клиент | D13: Личный кабинет — Предстоящие записи | E13: Просмотр, отмена и перенос своих записей | F13: =COUNTIF(Переходы!$C:$C,$A13) | G13: =COUNTIF(Переходы!$A:$A,$A13) | H13: =IF(F13=0,"Нет входа — недостижимый экран",IF(G13=0,"Нет выхода — тупик","OK"))
... A32: A11 | B32: Админ-панель | C32: Администратор | D32: Админ — Настройки | E32: График студии, правила записи, отмены и переносов | F32: =COUNTIF(Переходы!$C:$C,$A32) | G32: =COUNTIF(Переходы!$A:$A,$A32) | H32: =IF(F32=0,"Нет входа — недостижимый экран",IF(G32=0,"Нет выхода — тупик","OK"))

Sheet Переходы
A1: ID откуда | B1: Экран откуда | C1: ID куда | D1: Экран куда | E1: Действие или кнопка | F1: Тип перехода | G1: Примечание
A2: L1 | B2: Главная — лендинг | C2: B1 | D2: Запись. Шаг 1 — Услуги | E2: Кнопка «Записаться онлайн» | F2: Основной | G2: Главный призыв в шапке, первом экране и финальном блоке
A3: L1 | B3: Главная — лендинг | C3: B1 | D3: Запись. Шаг 1 — Услуги | E3: Кнопка «Записаться» в карточке услуги | F3: Основной | G3: Услуга отмечена заранее
A4: L1 | B4: Главная — лендинг | C4: B1 | D4: Запись. Шаг 1 — Услуги | E4: Кнопка «Записаться к мастеру» | F4: Основной | G4: Мастер выбран заранее
A5: L1 | B5: Главная — лендинг | C5: C1 | D5: Вход | E5: Ссылка «Войти» в шапке и подвале | F5: Основной
A6: L1 | B6: Главная — лендинг | C6: C2 | D6: Регистрация | E6: Ссылка «Регистрация» в подвале | F6: Основной
A7: C1 | B7: Вход | C7: K1 | D7: Личный кабинет — Предстоящие записи | E7: Кнопка «Войти» | F7: Основной | G7: Успешный вход вне процесса записи
A8: C1 | B8: Вход | C8: C2 | D8: Регистрация | E8: Ссылка «Зарегистрироваться» | F8: Основной
A9: C1 | B9: Вход | C9: C3 | D9: Восстановление пароля — запрос | E9: Ссылка «Забыли пароль?» | F9: Основной
A10: C1 | B10: Вход | C10: L1 | D10: Главная — лендинг | E10: Кнопка «Назад» и логотип | F10: Возврат
A11: C2 | B11: Регистрация | C11: K1 | D11: Личный кабинет — Предстоящие записи | E11: Кнопка «Зарегистрироваться» | F11: Основной | G11: После успешной регистрации
A12: C2 | B12: Регистрация | C12: C1 | D12: Вход | E12: Ссылка «Войти» | F12: Возврат | G12: В том числе из ошибки «E-mail уже зарегистрирован»
A13: C2 | B13: Регистрация | C13: L1 | D13: Главная — лендинг | E13: Кнопка «Назад» и логотип | F13: Возврат
A14: C3 | B14: Восстановление пароля — запрос | C14: C4 | D14: Восстановление пароля — новый пароль | E14: Переход по ссылке из письма | F14: Основной | G14: В прототипе — прямой переход
A15: C3 | B15: Восстановление пароля — запрос | C15: C1 | D15: Вход | E15: Ссылка «Вернуться ко входу» | F15: Возврат
A16: C4 | B16: Восстановление пароля — новый пароль | C16: K1 | D16: Личный кабинет — Предстоящие записи | E16: Кнопка «Сохранить и войти» | F16: Основной | G16: Если восстановление начато вне записи
A17: C4 | B17: Восстановление пароля — новый пароль | C17: B5 | D17: Запись. Шаг 5 — Подтверждение | E17: Кнопка «Сохранить и войти» | F17: Основной | G17: Если восстановление начато внутри записи и резерв ещё жив
A18: C4 | B18: Восстановление пароля — новый пароль | C18: C3 | D18: Восстановление пароля — запрос | E18: Кнопка «Запросить новую ссылку» | F18: Ошибка | G18: Состояние «Ссылка больше не действует»
A19: B1 | B19: Запись. Шаг 1 — Услуги | C19: B2 | D19: Запись. Шаг 2 — Мастер | E19: Кнопка «Далее» | F19: Основной | G19: Активна, если выбрана хотя бы одна услуга
A20: B1 | B20: Запись. Шаг 1 — Услуги | C20: L1 | D20: Главная — лендинг | E20: Кнопка «Назад» и логотип | F20: Возврат
A21: B2 | B21: Запись. Шаг 2 — Мастер | C21: B3 | D21: Запись. Шаг 3 — Дата и время | E21: Кнопка «Далее» | F21: Основной | G21: Активна после выбора мастера или «Любой мастер»
A22: B2 | B22: Запись. Шаг 2 — Мастер | C22: B1 | D22: Запись. Шаг 1 — Услуги | E22: Кнопка «Назад» и шаг «Услуги» | F22: Возврат | G22: Выбор услуг сохраняется
A23: B3 | B23: Запись. Шаг 3 — Дата и время | C23: B4 | D23: Запись. Шаг 4 — Вход в процессе записи | E23: Кнопка «Далее» для гостя | F23: Основной | G23: Слот резервируется на 10 минут
A24: B3 | B24: Запись. Шаг 3 — Дата и время | C24: B5 | D24: Запись. Шаг 5 — Подтверждение | E24: Кнопка «Далее» для авторизованного клиента | F24: Основной | G24: Шаг 4 пропускается, резерв уже идёт
A25: B3 | B25: Запись. Шаг 3 — Дата и время | C25: B2 | D25: Запись. Шаг 2 — Мастер | E25: Кнопка «Назад» и шаг «Мастер» | F25: Возврат | G25: Выбранное время сбрасывается
A26: B4 | B26: Запись. Шаг 4 — Вход в процессе записи | C26: B5 | D26: Запись. Шаг 5 — Подтверждение | E26: «Войти и продолжить» / «Создать аккаунт и продолжить» | F26: Основной | G26: Резерв продолжает идти
A27: B4 | B27: Запись. Шаг 4 — Вход в процессе записи | C27: B3 | D27: Запись. Шаг 3 — Дата и время | E27: Кнопка «Назад» | F27: Возврат | G27: Резерв сохраняется
A28: B4 | B28: Запись. Шаг 4 — Вход в процессе записи | C28: C3 | D28: Восстановление пароля — запрос | E28: Ссылка «Забыли пароль?» | F28: Основной | G28: Возврат на шаг 5 после смены пароля
A29: B4 | B29: Запись. Шаг 4 — Вход в процессе записи | C29: K1 | D29: Личный кабинет — Предстоящие записи | E29: Кнопка «Открыть мои записи» | F29: Ошибка | G29: Состояние «У вас уже есть запись к этому мастеру на это время»
A30: B5 | B30: Запись. Шаг 5 — Подтверждение | C30: B6 | D30: Запись подтверждена | E30: Кнопка «Подтвердить запись» / «Подтвердить перенос» | F30: Основной
A31: B5 | B31: Запись. Шаг 5 — Подтверждение | C31: B1 | D31: Запись. Шаг 1 — Услуги | E31: Ссылка «Изменить» у блока услуг | F31: Возврат
A32: B5 | B32: Запись. Шаг 5 — Подтверждение | C32: B2 | D32: Запись. Шаг 2 — Мастер | E32: Ссылка «Изменить» у блока мастера | F32: Возврат
A33: B5 | B33: Запись. Шаг 5 — Подтверждение | C33: B3 | D33: Запись. Шаг 3 — Дата и время | E33: Ссылка «Изменить» у блока времени, кнопка «Назад» | F33: Возврат
A34: B5 | B34: Запись. Шаг 5 — Подтверждение | C34: B3 | D34: Запись. Шаг 3 — Дата и время | E34: Кнопка «Выбрать другое время» | F34: Ошибка | G34: Состояния «Время заняли» и «Резерв истёк»
A35: B6 | B35: Запись подтверждена | C35: K1 | D35: Личный кабинет — Предстоящие записи | E35: Кнопка «Мои записи» | F35: Основной
A36: B6 | B36: Запись подтверждена | C36: L1 | D36: Главная — лендинг | E36: Кнопка «На главную» | F36: Возврат
A37: K1 | B37: Личный кабинет — Предстоящие записи | C37: K2 | D37: Личный кабинет — История | E37: Вкладка «История» | F37: Меню
A38: K1 | B38: Личный кабинет — Предстоящие записи | C38: K3 | D38: Перенос записи | E38: Кнопка «Перенести» | F38: Основной | G38: Недоступна при лимите 3 переноса и поздней отмене
A39: K1 | B39: Личный кабинет — Предстоящие записи | C39: K4 | D39: Личный кабинет — Уведомления | E39: Иконка уведомлений | F39: Меню
A40: K1 | B40: Личный кабинет — Предстоящие записи | C40: K5 | D40: Личный кабинет — Профиль | E40: Имя клиента в шапке | F40: Меню
...

Sheet Этапы связывания
A1: Этап | B1: Что связываем | C1: Экраны | D1: На что смотреть при проверке | E1: Статус
A2: 1 | B2: Оболочки и глобальная навигация | C2: Все экраны | D2: Единое поведение меню внутри каждой роли, подсветка активного пункта | E2: Не начат
A3: 2 | B3: Путь записи клиента | C3: L1, B1–B6 | D3: Шаги вперёд и назад, сохранение выбора, входы с лендинга | E3: Не начат
A4: 3 | B4: Авторизация и восстановление пароля | C4: C1–C4, B4 | D4: Возврат туда, откуда пришёл пользователь; сохранение резерва | E4: Не начат
A5: 4 | B5: Личный кабинет клиента | C5: K1–K5 | D5: Отмена, перенос, история, уведомления, выход | E5: Не начат
A6: 5 | B6: Состояния ошибок клиента | C6: B3, B5, C4, K1 | D6: Из каждой ошибки есть путь к действию | E6: Не начат
A7: 6 | B7: Кабинет мастера | C7: M1–M4 | D7: Свой день, расписание, профиль; нет доступа к чужим записям | E7: Не начат
A8: 7 | B8: Админ-панель | C8: A1–A11 | D8: Боковое меню, панели деталей, модальные окна, экспорт | E8: Не начат
A9: 8 | B9: Аудит связей | C9: Все экраны | D9: Поиск недостижимых экранов, тупиков, разрывов возврата и нарушений прав | E9: Не начат
